Workbook

Sheet 角色列表
A1: No. | B1: 种族 | C1: 名称 | D1: 攻击力 | E1: HP | F1: 特性 | G1: 技能 | H1: 配合 | I1: 克制 | J1: 被克制 | K1: 协同英雄 | L1: 属性评分 | M1: 特性评分 | N1: 技能量化 | O1: 技能评分 | P1: 补强 | Q1: 总评分 | R1: 分类 | S1: 语义伙伴
A2: 1 | B2: 人族 | C2: 伐木工 | D2: 3 | E2: 27 | G2: 攻击障碍物时额外减少99耐久。 | H2: 无 | L2: =D2*2.2+E2*0.45 -> 18.75 | M2: =SUM(IF(ISNUMBER(SEARCH("疾行",F2)),1.5,0), IF(ISNUMBER(SEARCH("渗透",F2)),1.5,0), IF(ISNUMBER(SEARCH("嘲讽",F2)),-1,0), IF(ISNUMBER(SEARCH("后勤",F2)),1,0)) -> 0 | N2: 0 | O2: =N2*2.2 -> 0 | Q2: =L2+M2+O2+P2 -> 18.75 | R2: 白板
A3: 2 | B3: 人族 | C3: 圣诞老人 | D3: 2 | E3: 24 | F3: <疾行> | G3: 己方回合开始时，在战场中的空地随机放置两个随机的增益道具，生成增益道具只能我方拾取，对方拾取则消失 | H3: 对攻击力收益大的角色，比如多倍伤害，AOE等 | L3: =D3*2.2+E3*0.45 -> 15.2 | M3: =SUM(IF(ISNUMBER(SEARCH("疾行",F3)),1.5,0), IF(ISNUMBER(SEARCH("渗透",F3)),1.5,0), IF(ISNUMBER(SEARCH("嘲讽",F3)),-1,0), IF(ISNUMBER(SEARCH("后勤",F3)),1,0)) -> 1.5 | N3: 0 | O3: =N3*2.2 -> 0 | P3: 1 | Q3: =L3+M3+O3+P3 -> 17.7 | R3: 辅助 | S3: 白游侠、末日、坠炮手、宿魂、涌电技师
A4: 3 | B4: 兽族 | C4: 毒蛇淑女 | D4: 1 | E4: 21 | G4: 攻击后，目标获得[猛毒]。 | I4: 圣光 | J4: 战锤 | L4: =D4*2.2+E4*0.45 -> 11.65 | M4: =SUM(IF(ISNUMBER(SEARCH("疾行",F4)),1.5,0), IF(ISNUMBER(SEARCH("渗透",F4)),1.5,0), IF(ISNUMBER(SEARCH("嘲讽",F4)),-1,0), IF(ISNUMBER(SEARCH("后勤",F4)),1,0)) -> 0 | N4: 3 | O4: =N4*2.2 -> 6.6 | Q4: =L4+M4+O4+P4 -> 18.25 | R4: 输出 | S4: 塔盾、装甲堡垒、复仇者
A5: 4 | B5: 兽族 | C5: 鼠队长 | D5: 4 | E5: 18 | F5: <疾行> | L5: =D5*2.2+E5*0.45 -> 16.9 | M5: =SUM(IF(ISNUMBER(SEARCH("疾行",F5)),1.5,0), IF(ISNUMBER(SEARCH("渗透",F5)),1.5,0), IF(ISNUMBER(SEARCH("嘲讽",F5)),-1,0), IF(ISNUMBER(SEARCH("后勤",F5)),1,0)) -> 1.5 | N5: 0 | O5: =N5*2.2 -> 0 | Q5: =L5+M5+O5+P5 -> 18.4 | R5: 白板
A6: 5 | B6: 魔族 | C6: 傀儡师 | D6: 3 | E6: 19 | F6: <远程> | G6: 己方回合开始时，令所有敌人向随机方向移动一格。 | H6: 需要敌人位移的角色，比如死神，烛火，炸弹人 | L6: =D6*2.2+E6*0.45 -> 15.15 | M6: =SUM(IF(ISNUMBER(SEARCH("疾行",F6)),1.5,0), IF(ISNUMBER(SEARCH("渗透",F6)),1.5,0), IF(ISNUMBER(SEARCH("嘲讽",F6)),-1,0), IF(ISNUMBER(SEARCH("后勤",F6)),1,0)) -> 0 | N6: 1 | O6: =N6*2.2 -> 2.2 | Q6: =L6+M6+O6+P6 -> 17.35 | R6: 辅助 | S6: 嬉皮死神×3、烛火×2、炸弹人×2
A7: 6 | B7: 人族 | C7: 医护兵 | D7: 3 | E7: 16 | F7: <远程> <疾行> | G7: 移动后，随机治疗相邻的队友中HP最低的角色之一。 | H7: 能提供攻击力加成的角色，最好搭配一个坦克 | L7: =D7*2.2+E7*0.45 -> 13.8 | M7: =SUM(IF(ISNUMBER(SEARCH("疾行",F7)),1.5,0), IF(ISNUMBER(SEARCH("渗透",F7)),1.5,0), IF(ISNUMBER(SEARCH("嘲讽",F7)),-1,0), IF(ISNUMBER(SEARCH("后勤",F7)),1,0)) -> 1.5 | N7: 3 | O7: =N7*0.45 -> 1.35 | Q7: =L7+M7+O7+P7 -> 16.65 | R7: 辅助
A8: 7 | B8: 人族 | C8: 影丸 | D8: 5 | E8: 14 | F8: <远程> <疾行> | H8: 最好搭配一个坦克 | L8: =D8*2.2+E8*0.45 -> 17.3 | M8: =SUM(IF(ISNUMBER(SEARCH("疾行",F8)),1.5,0), IF(ISNUMBER(SEARCH("渗透",F8)),1.5,0), IF(ISNUMBER(SEARCH("嘲讽",F8)),-1,0), IF(ISNUMBER(SEARCH("后勤",F8)),1,0)) -> 1.5 | O8: =N8*2.2 -> 0 | Q8: =L8+M8+O8+P8 -> 18.8 | R8: 白板
A9: 8 | B9: 精灵 | C9: 德鲁伊 | D9: 2 | E9: 20 | F9: <远程> | G9: 己方回合结束时，治疗所有其他队友（回复量=自己当前的攻击力）。 | H9: 能提供攻击力加成的角色 | L9: =D9*2.2+E9*0.45 -> 13.4 | M9: =SUM(IF(ISNUMBER(SEARCH("疾行",F9)),1.5,0), IF(ISNUMBER(SEARCH("渗透",F9)),1.5,0), IF(ISNUMBER(SEARCH("嘲讽",F9)),-1,0), IF(ISNUMBER(SEARCH("后勤",F9)),1,0)) -> 0 | N9: 4 | O9: =N9*0.45 -> 1.8 | Q9: =L9+M9+O9+P9 -> 15.2 | R9: 辅助 | S9: 烈焰祭司
A10: 9 | B10: 人族 | C10: 火枪手 | D10: 4 | E10: 20 | F10: <远程> | L10: =D10*2.2+E10*0.45 -> 17.8 | M10: =SUM(IF(ISNUMBER(SEARCH("疾行",F10)),1.5,0), IF(ISNUMBER(SEARCH("渗透",F10)),1.5,0), IF(ISNUMBER(SEARCH("嘲讽",F10)),-1,0), IF(ISNUMBER(SEARCH("后勤",F10)),1,0)) -> 0 | O10: =N10*2.2 -> 0 | Q10: =L10+M10+O10+P10 -> 17.8 | R10: 白板
A11: 10 | B11: 精灵 | C11: 白游侠 | D11: 2 | E11: 19 | F11: <远程> <疾行> | G11: 远程攻击时一并伤害与目标相邻的敌人，并使它们获得[冰冻]。 | H11: 能提供攻击力加成的角色 | L11: =D11*2.2+E11*0.45 -> 12.95 | M11: =SUM(IF(ISNUMBER(SEARCH("疾行",F11)),1.5,0), IF(ISNUMBER(SEARCH("渗透",F11)),1.5,0), IF(ISNUMBER(SEARCH("嘲讽",F11)),-1,0), IF(ISNUMBER(SEARCH("后勤",F11)),1,0)) -> 1.5 | N11: 2 | O11: =N11*2.2 -> 4.4 | Q11: =L11+M11+O11+P11 -> 18.85 | R11: 输出 | S11: 烈焰祭司
A12: 11 | B12: 人族 | C12: 塔盾 | D12: 1 | E12: 40 | F12: <嘲讽> | G12: 每当相邻队友受到多于1点的伤害时，你代替承受其中1点。 | L12: =D12*2.2+E12*0.45 -> 20.2 | M12: =SUM(IF(ISNUMBER(SEARCH("疾行",F12)),1.5,0), IF(ISNUMBER(SEARCH("渗透",F12)),1.5,0), IF(ISNUMBER(SEARCH("嘲讽",F12)),-1,0), IF(ISNUMBER(SEARCH("后勤",F12)),1,0)) -> -1 | N12: 0 | O12: =N12*2.2 -> 0 | Q12: =L12+M12+O12+P12 -> 19.2 | R12: 肉盾
A13: 12 | B13: 人族 | C13: 巨剑 | D13: 2 | E13: 24 | F13: <嘲讽> | G13: 攻击后，目标获得[重伤]。 | L13: =D13*2.2+E13*0.45 -> 15.2 | M13: =SUM(IF(ISNUMBER(SEARCH("疾行",F13)),1.5,0), IF(ISNUMBER(SEARCH("渗透",F13)),1.5,0), IF(ISNUMBER(SEARCH("嘲讽",F13)),-1,0), IF(ISNUMBER(SEARCH("后勤",F13)),1,0)) -> -1 | N13: 2 | O13: =N13*2.2 -> 4.4 | Q13: =L13+M13+O13+P13 -> 18.6 | R13: 肉盾
A14: 13 | B14: 兽族 | C14: 独脚龟 | D14: 2 | E14: 33 | F14: <嘲讽> | L14: =D14*2.2+E14*0.45 -> 19.25 | M14: =SUM(IF(ISNUMBER(SEARCH("疾行",F14)),1.5,0), IF(ISNUMBER(SEARCH("渗透",F14)),1.5,0), IF(ISNUMBER(SEARCH("嘲讽",F14)),-1,0), IF(ISNUMBER(SEARCH("后勤",F14)),1,0)) -> -1 | N14: 0 | O14: =N14*2.2 -> 0 | Q14: =L14+M14+O14+P14 -> 18.25 | R14: 肉盾
A15: 14 | B15: 魔族 | C15: 古拉博士 | D15: 4 | E15: 15 | G15: 攻击时，如果目标的HP大于自己，则治疗自己攻击数值血量。 | H15: 最好搭配一个坦克，能提供攻击力加成的角色 | L15: =D15*2.2+E15*0.45 -> 15.55 | M15: =SUM(IF(ISNUMBER(SEARCH("疾行",F15)),1.5,0), IF(ISNUMBER(SEARCH("渗透",F15)),1.5,0), IF(ISNUMBER(SEARCH("嘲讽",F15)),-1,0), IF(ISNUMBER(SEARCH("后勤",F15)),1,0)) -> 0 | N15: 4 | O15: =N15*0.45 -> 1.8 | Q15: =L15+M15+O15+P15 -> 17.35 | R15: 输出
A16: 15 | B16: 魔族 | C16: 小阴影 | D16: 3 | E16: 18 | F16: <疾行> | G16: 攻击时，若目标是全场HP最低的角色或之一，则造成2倍伤害。 | H16: 能提供攻击力加成的角色 | L16: =D16*2.2+E16*0.45 -> 14.7 | M16: =SUM(IF(ISNUMBER(SEARCH("疾行",F16)),1.5,0), IF(ISNUMBER(SEARCH("渗透",F16)),1.5,0), IF(ISNUMBER(SEARCH("嘲讽",F16)),-1,0), IF(ISNUMBER(SEARCH("后勤",F16)),1,0)) -> 1.5 | N16: 1.5 | O16: =N16*2.2 -> 3.3 | Q16: =L16+M16+O16+P16 -> 19.5 | R16: 输出
A17: 16 | B17: 机械 | C17: 波盾 | D17: 4 | E17: 16 | F17: <替补> | G17: 令己方所有角色获得[圣盾]。 | L17: =D17*2.2+E17*0.45 -> 16 | M17: =SUM(IF(ISNUMBER(SEARCH("疾行",F17)),1.5,0), IF(ISNUMBER(SEARCH("渗透",F17)),1.5,0), IF(ISNUMBER(SEARCH("嘲讽",F17)),-1,0), IF(ISNUMBER(SEARCH("后勤",F17)),1,0)) -> 0 | N17: 6 | O17: =N17*0.45 -> 2.7 | Q17: =L17+M17+O17+P17 -> 18.7 | R17: 辅助
A18: 17 | B18: 精灵 | C18: 烛火 | D18: 3 | E18: 17 | F18: <疾行> <后勤> | G18: 移动后，伤害所有相邻的敌人。 | H18: 能提供攻击力加成的角色 | L18: =D18*2.2+E18*0.45 -> 14.25 | M18: =SUM(IF(ISNUMBER(SEARCH("疾行",F18)),1.5,0), IF(ISNUMBER(SEARCH("渗透",F18)),1.5,0), IF(ISNUMBER(SEARCH("嘲讽",F18)),-1,0), IF(ISNUMBER(SEARCH("后勤",F18)),1,0)) -> 2.5 | N18: 2 | O18: =N18*2.2 -> 4.4 | Q18: =L18+M18+O18+P18 -> 21.15 | R18: 输出 | S18: 长剑
A19: 18 | B19: 人族 | C19: 长剑 | D19: 3 | E19: 18 | F19: <疾行> | G19: 攻击敌人时，一并伤害目标身后直线上的所有敌人。 | H19: 能提供攻击力加成的角色 | L19: =D19*2.2+E19*0.45 -> 14.7 | M19: =SUM(IF(ISNUMBER(SEARCH("疾行",F19)),1.5,0), IF(ISNUMBER(SEARCH("渗透",F19)),1.5,0), IF(ISNUMBER(SEARCH("嘲讽",F19)),-1,0), IF(ISNUMBER(SEARCH("后勤",F19)),1,0)) -> 1.5 | N19: 2 | O19: =N19*2.2 -> 4.4 | Q19: =L19+M19+O19+P19 -> 20.6 | R19: 输出 | S19: 烛火
A20: 19 | B20: 人族 | C20: 烈焰祭司 | D20: 1 | E20: 18 | F20: <远程> | G20: 己方回合开始时，所有其他队友攻击力+1，直到回合结束。 | H20: 需要攻击力加成的角色 | L20: =D20*2.2+E20*0.45 -> 10.3 | M20: =SUM(IF(ISNUMBER(SEARCH("疾行",F20)),1.5,0), IF(ISNUMBER(SEARCH("渗透",F20)),1.5,0), IF(ISNUMBER(SEARCH("嘲讽",F20)),-1,0), IF(ISNUMBER(SEARCH("后勤",F20)),1,0)) -> 0 | N20: 3 | O20: =N20*2.2 -> 6.6 | Q20: =L20+M20+O20+P20 -> 16.9 | R20: 辅助 | S20: 死灵法师、嬉皮死神、长角、小阴影
A21: 20 | B21: 人族 | C21: 赏金猎人 | D21: 3 | E21: 19 | F21: <远程> | G21: 远程攻击时，如果目标有<嘲讽>，则造成2倍伤害。 | H21: 能提供攻击力加成的角色 | I21: 塔盾、巨剑、独脚龟、圣光、复仇者、大骑士、战锤、雪拳、梅林、负墟、装甲堡垒、荆棘树人 | L21: =D21*2.2+E21*0.45 -> 15.15 | M21: =SUM(IF(ISNUMBER(SEARCH("疾行",F21)),1.5,0), IF(ISNUMBER(SEARCH("渗透",F21)),1.5,0), IF(ISNUMBER(SEARCH("嘲讽",F21)),-1,0), IF(ISNUMBER(SEARCH("后勤",F21)),1,0)) -> 0 | N21: 2 | O21: =N21*2.2 -> 4.4 | Q21: =L21+M21+O21+P21 -> 19.55 | R21: 输出
A22: 21 | B22: 精灵 | C22: 超新星 | D22: 3 | E22: 19 | F22: <远程> | G22: 远程攻击时，将与目标相邻的所有敌人击退1格。如果其后方有阻挡不能被击退，则伤害之。 | H22: 需要敌人位移的角色 | L22: =D22*2.2+E22*0.45 -> 15.15 | M22: =SUM(IF(ISNUMBER(SEARCH("疾行",F22)),1.5,0), IF(ISNUMBER(SEARCH("渗透",F22)),1.5,0), IF(ISNUMBER(SEARCH("嘲讽",F22)),-1,0), IF(ISNUMBER(SEARCH("后勤",F22)),1,0)) -> 0 | N22: 1.5 | O22: =N22*2.2 -> 3.3 | Q22: =L22+M22+O22+P22 -> 18.45 | R22: 辅助 | S22: 嬉皮死神×3、烛火×2
A23: 22 | B23: 精灵 | C23: 圣光 | D23: 2 | E23: 21 | F23: <嘲讽> | G23: 敌方回合，一名己方英雄受到伤害后，其获得[圣盾]，一回合限一次。 | L23: =D23*2.2+E23*0.45 -> 13.85 | M23: =SUM(IF(ISNUMBER(SEARCH("疾行",F23)),1.5,0), IF(ISNUMBER(SEARCH("渗透",F23)),1.5,0), IF(ISNUMBER(SEARCH("嘲讽",F23)),-1,0), IF(ISNUMBER(SEARCH("后勤",F23)),1,0)) -> -1 | N23: 3 | O23: =N23*0.45 -> 1.35 | P23: 4 | Q23: =L23+M23+O23+P23 -> 18.2 | R23: 肉盾
A24: 23 | B24: 人族 | C24: 复仇者 | D24: 2 | E24: 26 | F24: <嘲讽> | G24: 反击次数无限，反击时造成2倍伤害。 | J24: 影丸、火枪手、赏金猎人 | L24: =D24*2.2+E24*0.45 -> 16.1 | M24: =SUM(IF(ISNUMBER(SEARCH("疾行",F24)),1.5,0), IF(ISNUMBER(SEARCH("渗透",F24)),1.5,0), IF(ISNUMBER(SEARCH("嘲讽",F24)),-1,0), IF(ISNUMBER(SEARCH("后勤",F24)),1,0)) -> -1 | N24: 2 | O24: =N24*2.2 -> 4.4 | Q24: =L24+M24+O24+P24 -> 19.5 | R24: 肉盾
A25: 24 | B25: 人族 | C25: 大骑士 | D25: 2 | E25: 21 | F25: <嘲讽> | G25: 你的移动改为沿直线方向冲锋任意距离。然后你的攻击力上升等量于本次移动距离的值，直至回合结束。 | L25: =D25*2.2+E25*0.45 -> 13.85 | M25: =SUM(IF(ISNUMBER(SEARCH("疾行",F25)),1.5,0), IF(ISNUMBER(SEARCH("渗透",F25)),1.5,0), IF(ISNUMBER(SEARCH("嘲讽",F25)),-1,0), IF(ISNUMBER(SEARCH("后勤",F25)),1,0)) -> -1 | N25: 2 | O25: =N25*2.2 -> 4.4 | Q25: =L25+M25+O25+P25 -> 17.25 | R25: 肉盾
A26: 25 | B26: 人族 | C26: 战锤 | D26: 2 | E26: 24 | F26: <嘲讽> | G26: 攻击后令目标[麻痹][冰冻]，直至敌人回合结束。 | I26: 毒蛇淑女 | L26: =D26*2.2+E26*0.45 -> 15.2 | M26: =SUM(IF(ISNUMBER(SEARCH("疾行",F26)),1.5,0), IF(ISNUMBER(SEARCH("渗透",F26)),1.5,0), IF(ISNUMBER(SEARCH("嘲讽",F26)),-1,0), IF(ISNUMBER(SEARCH("后勤",F26)),1,0)) -> -1 | N26: 2 | O26: =N26*2.2 -> 4.4 | Q26: =L26+M26+O26+P26 -> 18.6 | R26: 肉盾
A27: 26 | B27: 人族 | C27: 雪拳 | D27: 2 | E27: 26 | F27: <嘲讽> <疾行> | G27: 移动后，令相邻敌人获得[冰冻]。 | L27: =D27*2.2+E27*0.45 -> 16.1 | M27: =SUM(IF(ISNUMBER(SEARCH("疾行",F27)),1.5,0), IF(ISNUMBER(SEARCH("渗透",F27)),1.5,0), IF(ISNUMBER(SEARCH("嘲讽",F27)),-1,0), IF(ISNUMBER(SEARCH("后勤",F27)),1,0)) -> 0.5 | N27: 1 | O27: =N27*2.2 -> 2.2 | Q27: =L27+M27+O27+P27 -> 18.8 | R27: 肉盾
A28: 27 | B28: 魔族 | C28: 暗域 | D28: 3 | E28: 20 | F28: <疾行> <渗透> | G28: 攻击时，和对象交换位置。 | H28: 需要敌人位移的角色 | L28: =D28*2.2+E28*0.45 -> 15.6 | M28: =SUM(IF(ISNUMBER(SEARCH("疾行",F28)),1.5,0), IF(ISNUMBER(SEARCH("渗透",F28)),1.5,0), IF(ISNUMBER(SEARCH("嘲讽",F28)),-1,0), IF(ISNUMBER(SEARCH("后勤",F28)),1,0)) -> 3 | N28: 1.5 | O28: =N28*2.2 -> 3.3 | Q28: =L28+M28+O28+P28 -> 21.9 | R28: 辅助 | S28: 嬉皮死神×3
A29: 28 | B29: 精灵 | C29: 古灵精怪 | D29: 3 | E29: 18 | G29: 我方回合开始时，随机变为己方队伍中的一名其他角色，暂时获得其所有技能和特性，直到下次变化为止。 | H29: 技能评分+补强>3的非替补角色 | L29: =D29*2.2+E29*0.45 -> 14.7 | M29: =SUM(IF(ISNUMBER(SEARCH("疾行",F29)),1.5,0), IF(ISNUMBER(SEARCH("渗透",F29)),1.5,0), IF(ISNUMBER(SEARCH("嘲讽",F29)),-1,0), IF(ISNUMBER(SEARCH("后勤",F29)),1,0)) -> 0 | N29: 2 | O29: =N29*2.2 -> 4.4 | Q29: =L29+M29+O29+P29 -> 19.1 | R29: 输出 | S29: 毒蛇淑女、白游侠、小阴影、烛火、长剑、赏金猎人、圣光、复仇者、暗域x2、嬉皮死神、长角、沉默术士、黄金矿工、风语者、宿魂、共鸣者、荆棘树人
A30: 29 | B30: 人族 | C30: 太阳斩 | D30: 3 | E30: 16 | F30: <替补> <疾行> | G30: 攻击力+3。每次攻击或反击后攻击力-1，直到恢复正常攻击力。 | L30: =D30*2.2+E30*0.45 -> 13.8 | M30: =SUM(IF(ISNUMBER(SEARCH("疾行",F30)),1.5,0), IF(ISNUMBER(SEARCH("渗透",F30)),1.5,0), IF(ISNUMBER(SEARCH("嘲讽",F30)),-1,0), IF(ISNUMBER(SEARCH("后勤",F30)),1,0)) -> 1.5 | N30: 1.5 | O30: =N30*2.2 -> 3.3 | Q30: =L30+M30+O30+P30 -> 18.6 | R30: 输出
A31: 30 | B31: 魔族 | C31: 嬉皮死神 | D31: 3 | E31: 20 | G31: 攻击时，如果目标没有与其他敌人相邻，则造成2倍伤害。 | H31: 能提供攻击力加成的角色 能使敌人位移的角色 | L31: =D31*2.2+E31*0.45 -> 15.6 | M31: =SUM(IF(ISNUMBER(SEARCH("疾行",F31)),1.5,0), IF(ISNUMBER(SEARCH("渗透",F31)),1.5,0), IF(ISNUMBER(SEARCH("嘲讽",F31)),-1,0), IF(ISNUMBER(SEARCH("后勤",F31)),1,0)) -> 0 | N31: 2 | O31: =N31*2.2 -> 4.4 | Q31: =L31+M31+O31+P31 -> 20 | R31: 输出 | S31: 傀儡师×3、超新星×3、暗域×3、长角、血锁×3
A32: 31 | B32: 魔族 | C32: 末日 | D32: 3 | E32: 18 | F32: <后勤> | G32: 移动后，伤害所有HP小于你的角色。 | L32: =D32*2.2+E32*0.45 -> 14.7 | M32: =SUM(IF(ISNUMBER(SEARCH("疾行",F32)),1.5,0), IF(ISNUMBER(SEARCH("渗透",F32)),1.5,0), IF(ISNUMBER(SEARCH("嘲讽",F32)),-1,0), IF(ISNUMBER(SEARCH("后勤",F32)),1,0)) -> 1 | N32: 1 | O32: =N32*2.2 -> 2.2 | Q32: =L32+M32+O32+P32 -> 17.9 | R32: 输出
A33: 32 | B33: 兽族 | C33: 长角 | D33: 2 | E33: 24 | G33: 攻击时，将目标击退1格。如果其后方有阻挡不能被击退，则造成2倍伤害。 | H33: 能提供攻击力加成的角色 | L33: =D33*2.2+E33*0.45 -> 15.2 | M33: =SUM(IF(ISNUMBER(SEARCH("疾行",F33)),1.5,0), IF(ISNUMBER(SEARCH("渗透",F33)),1.5,0), IF(ISNUMBER(SEARCH("嘲讽",F33)),-1,0), IF(ISNUMBER(SEARCH("后勤",F33)),1,0)) -> 0 | N33: 1.5 | O33: =N33*2.2 -> 3.3 | Q33: =L33+M33+O33+P33 -> 18.5 | R33: 输出
A34: 33 | B34: 魔族 | C34: 死灵法师 | D34: 1 | E34: 18 | F34: <远程> | G34: 己方回合开始时，随机在相邻的位置召唤2个骷髅兵。 | H34: 烈焰祭祀 | L34: =D34*2.2+E34*0.45 -> 10.3 | M34: =SUM(IF(ISNUMBER(SEARCH("疾行",F34)),1.5,0), IF(ISNUMBER(SEARCH("渗透",F34)),1.5,0), IF(ISNUMBER(SEARCH("嘲讽",F34)),-1,0), IF(ISNUMBER(SEARCH("后勤",F34)),1,0)) -> 0 | N34: 2.5 | O34: =N34*2.2 -> 5.5 | Q34: =L34+M34+O34+P34 -> 15.8 | R34: 输出 | S34: 烈焰祭司×3
A35: 34 | B35: 魔族 | C35: 沉默术士 | D35: 3 | E35: 15 | F35: <远程> <疾行> | G35: 远程攻击后，目标获得[沉默]。 | H35: 需搭配坦克 | I35: 毒蛇淑女、烛火x3、圣光、复仇者、暗域、古灵精怪、嬉皮死神、涌电技师、红帽x2、宿魂、共鸣者x3、荆棘树人 | L35: =D35*2.2+E35*0.45 -> 13.35 | M35: =SUM(IF(ISNUMBER(SEARCH("疾行",F35)),1.5,0), IF(ISNUMBER(SEARCH("渗透",F35)),1.5,0), IF(ISNUMBER(SEARCH("嘲讽",F35)),-1,0), IF(ISNUMBER(SEARCH("后勤",F35)),1,0)) -> 1.5 | N35: 3 | O35: =N35*2.2 -> 6.6 | Q35: =L35+M35+O35+P35 -> 21.45 | R35: 辅助
A36: 35 | B36: 机械 | C36: 炸弹人 | D36: 3 | E36: 20 | F36: <远程> | G36: 移动后，可在附近格子放置一颗炸弹。炸弹人以外的角色如果停留在该格就会引爆，受到5点伤害。 | H36: 能使敌人位移的角色，除了暗域 | L36: =D36*2.2+E36*0.45 -> 15.6 | M36: =SUM(IF(ISNUMBER(SEARCH("疾行",F36)),1.5,0), IF(ISNUMBER(SEARCH("渗透",F36)),1.5,0), IF(ISNUMBER(SEARCH("嘲讽",F36)),-1,0), IF(ISNUMBER(SEARCH("后勤",F36)),1,0)) -> 0 | N36: 2 | O36: =N36*2.2 -> 4.4 | Q36: =L36+M36+O36+P36 -> 20 | R36: 输出 | S36: 暗域、傀儡师、超新星、长角、血锁
A37: 36 | B37: 机械 | C37: 梅林 | D37: 2 | E37: 20 | F37: <嘲讽> <替补> | G37: 随机令HP最低的队友之一回复8点HP，然后与其交换位置。 | L37: =D37*2.2+E37*0.45 -> 13.4 | M37: =SUM(IF(ISNUMBER(SEARCH("疾行",F37)),1.5,0), IF(ISNUMBER(SEARCH("渗透",F37)),1.5,0), IF(ISNUMBER(SEARCH("嘲讽",F37)),-1,0), IF(ISNUMBER(SEARCH("后勤",F37)),1,0)) -> -1 | N37: 8 | O37: =N37*0.45 -> 3.6 | Q37: =L37+M37+O37+P37 -> 16 | R37: 肉盾
A38: 37 | B38: 兽族 | C38: 锤头鲨 | D38: 2 | E38: 20 | G38: 我方回合内，每当敌人受到一次伤害，你的攻击力+1，对方回合结束时消失。 | H38: 所有AOE和多段 | L38: =D38*2.2+E38*0.45 -> 13.4 | M38: =SUM(IF(ISNUMBER(SEARCH("疾行",F38)),1.5,0), IF(ISNUMBER(SEARCH("渗透",F38)),1.5,0), IF(ISNUMBER(SEARCH("嘲讽",F38)),-1,0), IF(ISNUMBER(SEARCH("后勤",F38)),1,0)) -> 0 | N38: 2 | O38: =N38*2.2 -> 4.4 | Q38: =L38+M38+O38+P38 -> 17.8 | R38: 输出 | S38: 白游侠、烛火、长剑、红帽、末日、死灵法师、超新星
A39: 38 | B39: 机械 | C39: 涌电技师 | D39: 0 | E39: 27 | F39: <后勤> | G39: 移动后，攻击力+1，然后随机伤害HP最低的敌人之一，然后伤害自己。 | L39: =D39*2.2+E39*0.45 -> 12.15 | M39: =SUM(IF(ISNUMBER(SEARCH("疾行",F39)),1.5,0), IF(ISNUMBER(SEARCH("渗透",F39)),1.5,0), IF(ISNUMBER(SEARCH("嘲讽",F39)),-1,0), IF(ISNUMBER(SEARCH("后勤",F39)),1,0)) -> 1 | N39: 2 | O39: =N39*2.2 -> 4.4 | Q39: =L39+M39+O39+P39 -> 17.55 | R39: 输出
A40: 39 | B40: 兽族 | C40: 猎颅者 | D40: 3 | E40: 17 | F40: <替补> | G40: 随机伤害HP最低的敌人之一，并令其获得[眩晕]。 | L40: =D40*2.2+E40*0.45 -> 14.25 | M40: =SUM(IF(ISNUMBER(SEARCH("疾行",F40)),1.5,0), IF(ISNUMBER(SEARCH("渗透",F40)),1.5,0), IF(ISNUMBER(SEARCH("嘲讽",F40)),-1,0), IF(ISNUMBER(SEARCH("后勤",F40)),1,0)) -> 0 | N40: 2 | O40: =N40*2.2 -> 4.4 | Q40: =L40+M40+O40+P40 -> 18.65 | R40: 辅助
...

Sheet 新角色畅想
A1: No. | B1: 种族 | C1: 名称 | D1: 攻击力 | E1: HP | F1: 特性 | G1: 技能 | H1: 配合 | I1: 克制 | J1: 被克制 | K1: 协同英雄 | L1: 属性评分 | M1: 特性评分 | N1: 技能量化 | O1: 技能评分 | P1: 补强 | Q1: 总评分 | R1: 分类 | S1: 语义伙伴 | T1: 玩法定位
A2: 50 | B2: 人族 | C2: 神射手 | D2: 3 | E2: 20 | F2: <远程> | G2: 若本回合没有移动，攻击力+2。 | H2: 能保护它的角色 | J2: 暗域、宿魂、大骑士 | L2: 15.6 | M2: 0 | N2: 1 | O2: 2.2 | Q2: 17.8 | R2: 输出 | S2: 塔盾、独脚龟、荆棘树人 | T2: 站桩才有输出
A3: 51 | B3: 机械 | C3: 蓄能兵 | D3: 2 | E3: 24 | G3: 若本回合没有攻击，则下回合攻击力+2（可累计，最多+4；攻击后清零）。 | H3: 最好搭配一个坦克 | J3: 沉默术士、猎颅者 | L3: 15.2 | M3: 0 | N3: 2 | O3: 4.4 | Q3: 19.6 | R3: 输出 | S3: 塔盾、圣光、复仇者 | T3: 蓄力-爆发节奏
A4: 52 | B4: 兽族 | C4: 狂战士 | D4: 2 | E4: 24 | F4: <嘲讽> | G4: 攻击力额外+（已损失HP ÷ 4）。 | H4: 能治疗自己的角色 | I4: 鼠队长、白游侠、死灵法师 | J4: 赏金猎人、影丸、红帽 | L4: 15.2 | M4: -1 | N4: 2 | O4: 4.4 | Q4: 18.6 | R4: 肉盾 | S4: 医护兵、德鲁伊、圣光 | T4: 血越少越猛
A5: 53 | B5: 魔族 | C5: 苦修者 | D5: 4 | E5: 16 | G5: 攻击后，自身受到2点伤害。 | H5: 能治疗自己的角色 | J5: 影丸、火枪手、坠炮手 | L5: 16 | M5: 0 | N5: 1.5 | O5: 3.3 | Q5: 19.3 | R5: 输出 | S5: 医护兵、德鲁伊、古拉博士 | T5: 自伤换伤害
A6: 55 | B6: 人族 | C6: 老兵 | D6: 3 | E6: 20 | G6: 每经过一个完整回合，永久攻击力+1（最多+3）。 | H6: 能保护它的角色 | J6: 沉默术士、影丸、火枪手 | L6: 15.6 | M6: 0 | N6: 1 | O6: 2.2 | Q6: 17.8 | R6: 输出 | S6: 塔盾、圣光、独脚龟 | T6: 越拖越强
A7: 56 | B7: 魔族 | C7: 噬魂者 | D7: 3 | E7: 18 | G7: 攻击后，若目标在本回合内死亡，回复8点HP。 | H7: 能造成高额伤害的角色 | J7: 塔盾、独脚龟 | L7: 14.7 | M7: 0 | N7: 1.5 | O7: 3.3 | Q7: 18 | R7: 输出 | S7: 影丸、小阴影、赏金猎人 | T7: 击杀即续航
A8: 57 | B8: 兽族 | C8: 食尸鬼 | D8: 4 | E8: 17 | G8: 击杀敌人后，永久攻击力+1（最多+3）。 | H8: 能压低敌人HP的角色 | J8: 塔盾、独脚龟、装甲堡垒 | L8: 16.45 | M8: 0 | N8: 1 | O8: 2.2 | Q8: 18.65 | R8: 输出 | S8: 影丸、小阴影、赏金猎人 | T8: 抢人头滚雪球
A9: 60 | B9: 机械 | C9: 破盾锤 | D9: 3 | E9: 20 | G9: 攻击无视目标的[圣盾]；若目标带有[圣盾]，本次伤害翻倍。 | H9: 能提供攻击力加成的角色 | I9: 波盾、圣光 | J9: 塔盾、独脚龟、装甲堡垒 | L9: 15.6 | M9: 0 | N9: 2 | O9: 4.4 | Q9: 20 | R9: 输出 | S9: 烈焰祭司、圣诞老人 | T9: 专破圣盾
A10: 62 | B10: 精灵 | C10: 星火法师 | D10: 2 | E10: 22 | F10: <远程> | G10: 攻击后，对目标相邻的另一个敌人造成2点伤害。 | H10: 能使敌人聚拢的角色 | J10: 塔盾、独脚龟 | L10: 14.3 | M10: 0 | N10: 2 | O10: 4.4 | Q10: 18.7 | R10: 输出 | S10: 傀儡师、血锁、长角 | T10: 溅射逼走位
A11: 63 | B11: 兽族 | C11: 毒牙猎手 | D11: 3 | E11: 18 | F11: <远程> | G11: 攻击时，若目标带有任意负面状态，伤害+2。 | H11: 能施加负面状态的角色 | J11: 负墟、圣光 | L11: 14.7 | M11: 0 | N11: 1.5 | O11: 3.3 | Q11: 18 | R11: 输出 | S11: 毒蛇淑女、战锤、雪拳、巨剑、荆棘树人 | T11: 专打带状态的敌人
A12: 64 | B12: 兽族 | C12: 狼骑士 | D12: 4 | E12: 16 | F12: <疾行> | G12: 若本回合移动了3格或更多，本次攻击伤害+2。 | H12: 能提供移动力的角色 | J12: 影丸、火枪手、坠炮手 | L12: 16 | M12: 1.5 | N12: 1 | O12: 2.2 | Q12: 19.7 | R12: 输出 | S12: 风语者、大骑士 | T12: 长距离冲刺
A13: 65 | B13: 魔族 | C13: 猩红骑士 | D13: 4 | E13: 18 | F13: <疾行> | G13: 移动后，回复等同于本次移动距离的HP。 | H13: 能提供移动力的角色 | J13: 影丸、火枪手、坠炮手 | L13: 16.9 | M13: 1.5 | N13: 2 | O13: 0.9 | Q13: 19.3 | R13: 输出 | S13: 风语者、大骑士、宿魂 | T13: 打带跑续航
A14: 66 | B14: 兽族 | C14: 掠夺者 | D14: 3 | E14: 20 | G14: 攻击后，偷取目标1点攻击力（永久，最多+3）。 | H14: 能保护它的角色 | I14: 塔盾、装甲堡垒、古拉博士 | J14: 影丸、火枪手、坠炮手 | L14: 15.6 | M14: 0 | N14: 1 | O14: 2.2 | Q14: 17.8 | R14: 输出 | S14: 塔盾、独脚龟、圣光 | T14: 专偷高攻单位
A15: 67 | B15: 机械 | C15: 铆钉炮台 | D15: 3 | E15: 17 | F15: <后勤> | G15: 己方回合结束时，对最近的敌人造成3点伤害。 | H15: 能保护它的角色 | J15: 影丸、火枪手、暗域 | L15: 14.25 | M15: 1 | N15: 2 | O15: 4.4 | Q15: 19.65 | R15: 输出 | S15: 塔盾、独脚龟、荆棘树人 | T15: 推着走的炮台
A16: 68 | B16: 兽族 | C16: 山猪撞角 | D16: 3 | E16: 22 | G16: 攻击后，将目标击退1格；若目标撞上其他单位，双方各受2点伤害。 | H16: 需要敌人位移的角色 | J16: 塔盾、装甲堡垒 | L16: 16.5 | M16: 0 | N16: 1 | O16: 2.2 | Q16: 18.7 | R16: 肉盾 | S16: 超新星、长角、血锁 | T16: 撞人连锁伤
A17: 69 | B17: 机械 | C17: 自爆机兵 | D17: 3 | E17: 18 | G17: 阵亡时，对相邻的所有敌人造成6点伤害。 | H17: 能把它送进人堆的角色 | J17: 沉默术士、猎颅者、坠炮手 | L17: 14.7 | M17: 0 | N17: 2 | O17: 4.4 | Q17: 19.1 | R17: 输出 | S17: 暗域、宿魂、大骑士 | T17: 死亡威慑
A18: 70 | B18: 机械 | C18: 磁石兵 | D18: 2 | E18: 24 | G18: 己方回合开始时，将相邻的所有敌人拉近1格。 | H18: 能承受集火的角色 | J18: 影丸、火枪手、坠炮手 | L18: 15.2 | M18: 0 | N18: 2 | O18: 4.4 | Q18: 19.6 | R18: 辅助 | S18: 烛火、末日、白游侠 | T18: 把敌人拽过来
A19: 71 | B19: 精灵 | C19: 潮汐师 | D19: 3 | E19: 22 | G19: 攻击后，将目标推开1格，然后自己移动到目标原来的位置。 | H19: 能提供攻击力加成的角色 | J19: 复仇者、荆棘树人 | L19: 16.5 | M19: 0 | N19: 1 | O19: 2.2 | Q19: 18.7 | R19: 输出 | S19: 烈焰祭司、圣诞老人 | T19: 推开并抢占位置
A20: 72 | B20: 精灵 | C20: 换位僧 | D20: 2 | E20: 26 | G20: 移动后，可与相邻的任意单位（含敌人）交换位置。 | H20: 最好搭配一个坦克 | J20: 影丸、火枪手、傀儡师 | L20: 16.1 | M20: 0 | N20: 1 | O20: 2.2 | Q20: 18.3 | R20: 辅助 | S20: 梅林、医护兵、德鲁伊 | T20: 把谁放到哪
A21: 73 | B21: 精灵 | C21: 霜语者 | D21: 1 | E21: 28 | F21: <远程> | G21: 己方回合开始时，令所有敌人获得[冰冻]，对方回合结束时解除。 | H21: 近战角色 | I21: 风语者、影丸、鼠队长 | J21: 负墟 | L21: 14.8 | M21: 0 | N21: 2 | O21: 4.4 | Q21: 19.2 | R21: 辅助 | S21: 长剑、暗域、大骑士 | T21: 全场减速
A22: 74 | B22: 机械 | C22: 干扰者 | D22: 2 | E22: 24 | G22: 相邻的敌人无法使用技能。 | H22: 能保护它的角色 | I22: 烛火、圣光、复仇者、暗域、古灵精怪、嬉皮死神、涌电技师、红帽、宿魂、共鸣者、荆棘树人、沉默术士 | J22: 影丸、火枪手、坠炮手 | L22: 15.2 | M22: 0 | N22: 2 | O22: 4.4 | Q22: 19.6 | R22: 辅助 | S22: 塔盾、独脚龟 | T22: 贴脸封技能
A23: 75 | B23: 人族 | C23: 伪旗手 | D23: 2 | E23: 30 | F23: <嘲讽> | G23: 己方回合开始时，令相邻的一名队友获得[嘲讽]，直到回合结束。 | H23: 能站在后排输出的角色 | J23: 赏金猎人、影丸、火枪手 | L23: 17.9 | M23: -1 | N23: 1 | O23: 2.2 | Q23: 19.1 | R23: 肉盾 | S23: 影丸、火枪手、坠炮手 | T23: 操控敌人打谁
A24: 76 | B24: 机械 | C24: 反伤机兵 | D24: 1 | E24: 31 | F24: <嘲讽> | G24: 受到近战攻击时，对攻击者造成2点伤害。 | H24: 能提供圣盾或治疗的角色 | I24: 鼠队长、太阳斩、嬉皮死神 | J24: 影丸、火枪手、坠炮手 | L24: 16.15 | M24: -1 | N24: 2 | O24: 4.4 | Q24: 19.55 | R24: 肉盾 | S24: 圣光、荆棘树人 | T24: 近战不敢碰
A25: 77 | B25: 精灵 | C25: 荆棘卫士 | D25: 2 | E25: 26 | G25: 受到远程攻击时，对攻击者造成2点伤害。 | H25: 能提供治疗的角色 | I25: 白游侠、坠炮手、风语者、烈焰祭司 | J25: 影丸、火枪手、战锤 | L25: 16.1 | M25: 0 | N25: 1 | O25: 2.2 | Q25: 18.3 | R25: 肉盾 | S25: 医护兵、德鲁伊、圣光 | T25: 远程不敢点
A26: 78 | B26: 人族 | C26: 重装步兵 | D26: 2 | E26: 30 | F26: <嘲讽> | G26: 受到的伤害小于3时，改为0。 | H26: 能治疗自己的角色 | I26: 鼠队长、死灵法师、猎颅者、白游侠 | J26: 影丸、红帽、古拉博士 | L26: 17.9 | M26: -1 | N26: 3 | O26: 1.35 | Q26: 18.25 | R26: 肉盾 | S26: 医护兵、德鲁伊、圣光 | T26: 免疫小伤害
A27: 79 | B27: 精灵 | C27: 卸力僧 | D27: 2 | E27: 22 | G27: 攻击后，令目标本回合无法反击。自身反击时造成2倍伤害。 | H27: 能提供攻击力加成的角色 | I27: 复仇者、塔盾、装甲堡垒、荆棘树人、战锤、负墟 | J27: 影丸、火枪手、坠炮手 | L27: 14.3 | M27: 0 | N27: 2 | O27: 4.4 | Q27: 18.7 | R27: 肉盾 | S27: 医护兵、德鲁伊、风语者 | T27: 禁反击
A28: 80 | B28: 精灵 | C28: 冰霜守卫 | D28: 1 | E28: 32 | F28: <嘲讽> | G28: 被攻击后，令攻击者获得[冰冻]，直到其回合结束。 | H28: 能提供治疗的角色 | I28: 鼠队长、太阳斩、嬉皮死神 | J28: 负墟、影丸、火枪手 | L28: 16.6 | M28: -1 | N28: 1 | O28: 2.2 | Q28: 17.8 | R28: 肉盾 | S28: 医护兵、德鲁伊 | T28: 挨打就冻住对方
A29: 81 | B29: 兽族 | C29: 盾击兵 | D29: 2 | E29: 30 | F29: <嘲讽> | G29: 攻击后，将目标击退1格。 | H29: 需要敌人位移的角色 | J29: 赏金猎人、影丸、火枪手 | L29: 17.9 | M29: -1 | N29: 1 | O29: 2.2 | Q29: 19.1 | R29: 肉盾 | S29: 超新星、长角、血锁 | T29: 盾撞击退
A30: 82 | B30: 兽族 | C30: 蛮牛卫士 | D30: 1 | E30: 35 | F30: <嘲讽> | G30: 回合结束时，若本回合没有移动，回复5点HP。 | H30: 能治疗或提供圣盾的角色 | J30: 赏金猎人、沉默术士、影丸 | L30: 17.95 | M30: -1 | N30: 5 | O30: 2.25 | Q30: 19.2 | R30: 肉盾 | S30: 装甲堡垒、独脚龟 | T30: 守株待兔回血
A31: 83 | B31: 人族 | C31: 哨兵 | D31: 2 | E31: 24 | F31: <嘲讽> | G31: 若本回合没有攻击，回合结束时获得[圣盾]。 | H31: 能提供攻击力加成的角色 | J31: 赏金猎人、沉默术士、影丸 | L31: 15.2 | M31: -1 | N31: 2 | O31: 4.4 | Q31: 18.6 | R31: 肉盾 | S31: 塔盾、装甲堡垒 | T31: 打或守的抉择
A32: 84 | B32: 机械 | C32: 铁盾卫士 | D32: 1 | E32: 36 | F32: <嘲讽> | G32: 相邻的队友受到的远程伤害-1。 | H32: 需要贴身保护的远程角色 | I32: 白游侠、影丸、火枪手 | J32: 赏金猎人、烛火、末日 | L32: 18.4 | M32: -1 | N32: 3 | O32: 1.35 | Q32: 18.75 | R32: 肉盾 | S32: 塔盾、独脚龟、医护兵 | T32: 掩护后排
A33: 85 | B33: 人族 | C33: 军旗手 | D33: 2 | E33: 30 | F33: <嘲讽> | G33: 阵亡时，令所有队友永久获得攻击力+1。 | H33: 能保护它的角色 | J33: 沉默术士、猎颅者、赏金猎人 | L33: 17.9 | M33: -1 | N33: 1 | O33: 2.2 | Q33: 19.1 | R33: 肉盾 | S33: 影丸、红帽、共鸣者 | T33: 死了也给全队加攻
A34: 86 | B34: 精灵 | C34: 净化祭司 | D34: 2 | E34: 18 | F34: <远程> | G34: 己方回合开始时，清除所有队友身上的负面状态；每清除一个，本回合自身攻击力+1（最多+3）。 | H34: 需要站在前排的角色 | I34: 战锤、雪拳、巨剑、沉默术士、荆棘树人、宿魂、猎颅者、白游侠 | J34: 影丸、火枪手、毒蛇淑女 | L34: 12.5 | M34: 0 | N34: 3 | O34: 6.6 | Q34: 19.1 | R34: 辅助 | S34: 塔盾、装甲堡垒、独脚龟 | T34: 全队解状态
A35: 87 | B35: 魔族 | C35: 瘟疫使者 | D35: 2 | E35: 21 | G35: 攻击后，令目标无法回复HP，直到对方回合结束。 | H35: 能施加负面状态的角色 | I35: 德鲁伊、医护兵、梅林、古拉博士、塔盾、复仇者、风语者 | J35: 负墟、圣光 | L35: 13.85 | M35: 0 | N35: 2 | O35: 4.4 | Q35: 18.25 | R35: 输出 | S35: 毒蛇淑女、战锤、雪拳、巨剑、荆棘树人、沉默术士 | T35: 掐断回血
A36: 88 | B36: 人族 | C36: 战地医师 | D36: 2 | E36: 28 | F36: <远程> | G36: 己方回合结束时，治疗相邻的所有队友2点HP。 | H36: 需要站在前排的角色 | J36: 沉默术士、影丸、火枪手 | L36: 17 | M36: 0 | N36: 3 | O36: 1.35 | Q36: 18.35 | R36: 辅助 | S36: 塔盾、装甲堡垒、独脚龟 | T36: 抱团才回血
A37: 89 | B37: 魔族 | C37: 鲜血祭司 | D37: 2 | E37: 24 | G37: 攻击后，回复相邻队友3点HP。 | H37: 能站在前排的角色 | J37: 沉默术士、影丸、火枪手 | L37: 15.2 | M37: 0 | N37: 2 | O37: 4.4 | Q37: 19.6 | R37: 辅助 | S37: 塔盾、独脚龟、荆棘树人 | T37: 边打边奶
A38: 90 | B38: 机械 | C38: 圣盾工匠 | D38: 1 | E38: 30 | F38: <远程> | G38: 己方回合开始时，令相邻的一名队友获得[圣盾]。 | H38: 需要保护的队友 | J38: 沉默术士、影丸、火枪手 | L38: 15.7 | M38: 0 | N38: 1.5 | O38: 3.3 | Q38: 19 | R38: 辅助 | S38: 塔盾、装甲堡垒、独脚龟 | T38: 贴着谁谁有盾
A39: 91 | B39: 兽族 | C39: 战吼者 | D39: 3 | E39: 20 | G39: 攻击后，令相邻的队友攻击力+1，直到回合结束。 | H39: 需要攻击力加成的角色 | J39: 沉默术士、影丸、火枪手 | L39: 15.6 | M39: 0 | N39: 1.5 | O39: 3.3 | Q39: 18.9 | R39: 辅助 | S39: 影丸、红帽、鼠队长 | T39: 冲上去开团
A40: 92 | B40: 兽族 | C40: 狂徒 | D40: 6 | E40: 13 | H40: 最好搭配一个坦克 | J40: 影丸、火枪手、坠炮手 | L40: 19.05 | M40: 0 | N40: 0 | O40: 0 | Q40: 19.05 | R40: 白板 | S40: 塔盾、圣光、复仇者 | T40: 面板攻6空档
...

Sheet 数据统计
A5: 数据统计
A6: 种族 | B6: 数量
A7: 精灵 | B7: =COUNTIF(角色列表!B:B,数据统计!A7) -> 9
A8: 人族 | B8: =COUNTIF(角色列表!B:B,数据统计!A8) -> 18
A9: 魔族 | B9: =COUNTIF(角色列表!B:B,数据统计!A9) -> 11
A10: 兽族 | B10: =COUNTIF(角色列表!B:B,数据统计!A10) -> 6
A11: 机械 | B11: =COUNTIF(角色列表!B:B,数据统计!A11) -> 5
A13: 类型 | B13: 数量
A14: 肉盾 | B14: =COUNTIF(角色列表!R:R,数据统计!A14) -> 12
A15: 输出 | B15: =COUNTIF(角色列表!R:R,数据统计!A15) -> 20
A16: 辅助 | B16: =COUNTIF(角色列表!R:R,数据统计!A16) -> 12
A17: 白板 | B17: =COUNTIF(角色列表!R:R,数据统计!A17) -> 5

Sheet 词条解释
A4: <特性>
A5: 没有特殊注明的所有角色的移动力都是2，射程都是1。
A6: 特性 | B6: 效果
A7: <远程> | B7: 这个角色没有敌人相邻的话，射程+1。有敌人相邻的话，基础攻击力变为1。
A8: <嘲讽> | B8: 一名角色攻击时，攻击范围内有任何对方角色拥有<嘲讽>的话，只能从拥有<嘲讽>的对象中选择攻击目标。
A9: <疾行> | B9: 这个角色移动力+1。
A10: <替补> | B10: 这个角色替补登场的时候，触发技能效果
A11: <后勤> | B11: 这个角色不能主动攻击。可以反击。
A12: <渗透> | B12: 这个角色移动时可穿透角色和障碍物，不能停留。
A14: [状态]
A15: 状态 | B15: 效果
A16: [重伤] | B16: 受到的伤害+1。对方回合结束时解除。
A17: [麻痹] | B17: 攻击力-1（至少为0）。对方回合结束时解除。
A18: [冰冻] | B18: 移动力-1（至少为0）。对方回合结束时解除。
A19: [沉默] | B19: 不能触发技能，对方回合结束时解除。
A20: [眩晕] | B20: 不能移动、攻击、反击和触发非关键词技能，对方回合结束时解除。
A21: [猛毒] | B21: 每个回合开始时受到1点伤害。无法解除。
A22: [附体] | B22: 与施加者伤害绑定。施加者受到伤害时，目标受到同等伤害。对方回合结束时解除。
A23: [圣盾] | B23: 防止一次受到的伤害，生效时解除。
A24: [坚固] | B24: 受到攻击伤害-1，对方回合结束时解除。
A25: [荆棘] | B25: 无法移动，对方回合结束时解除
A26: 同类标记效果均不叠加。

Sheet 平衡调整
A1: 单体价值 S = | B1: 攻×2.2 + HP×0.45+特性评分+技能评分
C12: 白板模板 | D12: 基数 | E12: 18.75 | G12: 特性影响
C13: 攻击 | D13: 血量 | E13: 评分 | G13: 特性 | H13: 评分
C14: 1 | D14: =ROUND((E14-2.2*C14)/0.45,0) -> 37 | E14: =$E$12 -> 18.75 | G14: 嘲讽 | H14: -1
C15: 2 | D15: =ROUND((E15-2.2*C15)/0.45,0) -> 32 | E15: =$E$12 -> 18.75 | G15: 疾行 | H15: 1.5
C16: 3 | D16: =ROUND((E14-2.2*C16)/0.45,0) -> 27 | E16: =$E$12 -> 18.75 | G16: 替补 | H16: 0
C17: 4 | D17: =ROUND((E15-2.2*C17)/0.45,0) -> 22 | E17: =$E$12 -> 18.75 | G17: 渗透 | H17: 1.5
C18: 5 | D18: =ROUND((E16-2.2*C18)/0.45,0) -> 17 | E18: =$E$12 -> 18.75 | G18: 后勤 | H18: 1
